Workbook
Name FRAIS_D_ENVOI: Feuil3!$A$2:$C$27

Sheet Feuil3
A1: BORNE INFERIEURE | B1: BORNE SUPERIEURE | C1: VALEUR
A2: 1 | B2: 500 | C2: 25
A3: 501 | B3: 1500 | C3: 100
A4: 1501 | B4: 3000 | C4: 200
A5: 3001 | B5: 5000 | C5: 400
A6: 5001 | B6: 10000 | C6: 700
A7: 10001 | B7: 15000 | C7: 1100
A8: 15001 | B8: 20000 | C8: 1300
A9: 20001 | B9: 25000 | C9: 1500
A10: 25001 | B10: 30000 | C10: 1700
A11: 30001 | B11: 50000 | C11: 1800
A12: 50001 | B12: 60000 | C12: 2300
A13: 60001 | B13: 75000 | C13: 2700
... A28: 2000001 | B28: 3000000 | C28: 0.02

Sheet Feuil7

Sheet Feuil6

Sheet Feuil4

Sheet Feuil1
A1: TONTINE | F1: CREDIT

Sheet RAPPORTS
C2: Rapport Manuel de fin de journée
CD3: Antoine Michel DIOUF
A4: Code : | B4: WKSDF | J4: Date et heure | L4: 45390.462 | CD4: Ndiogou FAYE | DF4: =NOW() -> 45390.722
A5: Agence : | B5: SOKHNA DIENG | DF5: NON REMONTEE
A6: Opérateur : | DF6: DOUBLON | IE6: 30000
H7: 269780 | J7: PV de caisse | DF7: REMONTEE
A9: Activités | B9: Plafond | D9: Encaissement (+) | F9: Décaissement (-) | H9: Solde | J9: Coupures | K9: Nbre | L9: Montant
B10: Ouverture | C10: Clôture | D10: Montant | E10: Nbre | F10: Montant | G10: Nbre | J10: 5 | K10: 0 | L10: =J10*K10 -> 0
A11: Alimentation | D11: 750000 | J11: 10 | K11: 3 | L11: =J11*K11 -> 30
A12: Prêt/Versement | J12: 25 | K12: 6 | L12: =J12*K12 -> 150 | BV12: n
A13: WAVE | B13: 551100 | C13: 430230 | D13: =SUMIFS(TRANSACTIONS!$H:$H,TRANSACTIONS!$B:$B,DATE(YEAR(RAPPORTS!$L$4),MONTH(RAPPORTS!$L$4),DAY(RAPPORTS!$L$4)),TRANSACTIONS!$D:$D,RAPPORTS!$A13,TRANSACTIONS!$E:$E,RAPPORTS!D$9) -> 2216350 | E13: =COUNTIFS(TRANSACTIONS!$B:$B,DATE(YEAR(RAPPORTS!$L$4),MONTH(RAPPORTS!$L$4),DAY(RAPPORTS!$L$4)),TRANSACTIONS!$D:$D,RAPPORTS!$A13,TRANSACTIONS!$E:$E,RAPPORTS!D$9) -> 35 | F13: =SUMIFS(TRANSACTIONS!$H:$H,TRANSACTIONS!$B:$B,DATE(YEAR(RAPPORTS!$L$4),MONTH(RAPPORTS!$L$4),DAY(RAPPORTS!$L$4)),TRANSACTIONS!$D:$D,RAPPORTS!$A13,TRANSACTIONS!$E:$E,RAPPORTS!F$9) -> 727300 | G13: =COUNTIFS(TRANSACTIONS!$B:$B,DATE(YEAR(RAPPORTS!$L$4),MONTH(RAPPORTS!$L$4),DAY(RAPPORTS!$L$4)),TRANSACTIONS!$D:$D,RAPPORTS!$A13,TRANSACTIONS!$E:$E,RAPPORTS!F$9) -> 35 | H13: =D13-F13 -> 1489050 | J13: 50 | K13: 150 | L13: =+K13*J13 -> 7500
A14: WOYAFAL | C14: 38053.45 | E14: =COUNTIFS(TRANSACTIONS!$B:$B,DATE(YEAR(RAPPORTS!$L$4),MONTH(RAPPORTS!$L$4),DAY(RAPPORTS!$L$4)),TRANSACTIONS!$D:$D,RAPPORTS!$A14,TRANSACTIONS!$E:$E,RAPPORTS!D$9) -> 0 | F14: =SUMIFS(TRANSACTIONS!$H:$H,TRANSACTIONS!$B:$B,DATE(YEAR(RAPPORTS!$L$4),MONTH(RAPPORTS!$L$4),DAY(RAPPORTS!$L$4)),TRANSACTIONS!$D:$D,RAPPORTS!$A15,TRANSACTIONS!$E:$E,RAPPORTS!F$9) -> 0 | G14: =COUNTIFS(TRANSACTIONS!$B:$B,DATE(YEAR(RAPPORTS!$L$4),MONTH(RAPPORTS!$L$4),DAY(RAPPORTS!$L$4)),TRANSACTIONS!$D:$D,RAPPORTS!$A14,TRANSACTIONS!$E:$E,RAPPORTS!F$9) -> 0 | H14: 0
A15: SEDDO | D15: =SUMIFS(TRANSACTIONS!$H:$H,TRANSACTIONS!$B:$B,DATE(YEAR(RAPPORTS!$L$4),MONTH(RAPPORTS!$L$4),DAY(RAPPORTS!$L$4)),TRANSACTIONS!$D:$D,RAPPORTS!$A15,TRANSACTIONS!$E:$E,RAPPORTS!D$9) -> 4000 | E15: =COUNTIFS(TRANSACTIONS!$B:$B,DATE(YEAR(RAPPORTS!$L$4),MONTH(RAPPORTS!$L$4),DAY(RAPPORTS!$L$4)),TRANSACTIONS!$D:$D,RAPPORTS!$A15,TRANSACTIONS!$E:$E,RAPPORTS!D$9) -> 3 | F15: =SUMIFS(TRANSACTIONS!$H:$H,TRANSACTIONS!$B:$B,DATE(YEAR(RAPPORTS!$L$4),MONTH(RAPPORTS!$L$4),DAY(RAPPORTS!$L$4)),TRANSACTIONS!$D:$D,RAPPORTS!$A15,TRANSACTIONS!$E:$E,RAPPORTS!F$9) -> 0 | G15: =COUNTIFS(TRANSACTIONS!$B:$B,DATE(YEAR(RAPPORTS!$L$4),MONTH(RAPPORTS!$L$4),DAY(RAPPORTS!$L$4)),TRANSACTIONS!$D:$D,RAPPORTS!$A15,TRANSACTIONS!$E:$E,RAPPORTS!F$9) -> 0 | H15: =D15-F15 -> 4000 | J15: 100 | K15: 81 | L15: =J15*K15 -> 8100
A16: Orange Money | B16: 316052.45 | D16: =SUMIFS(TRANSACTIONS!$H:$H,TRANSACTIONS!$B:$B,DATE(YEAR(RAPPORTS!$L$4),MONTH(RAPPORTS!$L$4),DAY(RAPPORTS!$L$4)),TRANSACTIONS!$D:$D,RAPPORTS!$A16,TRANSACTIONS!$E:$E,RAPPORTS!D$9) -> 272000 | E16: =COUNTIFS(TRANSACTIONS!$B:$B,DATE(YEAR(RAPPORTS!$L$4),MONTH(RAPPORTS!$L$4),DAY(RAPPORTS!$L$4)),TRANSACTIONS!$D:$D,RAPPORTS!$A16,TRANSACTIONS!$E:$E,RAPPORTS!D$9) -> 5 | F16: =SUMIFS(TRANSACTIONS!$H:$H,TRANSACTIONS!$B:$B,DATE(YEAR(RAPPORTS!$L$4),MONTH(RAPPORTS!$L$4),DAY(RAPPORTS!$L$4)),TRANSACTIONS!$D:$D,RAPPORTS!$A16,TRANSACTIONS!$E:$E,RAPPORTS!F$9) -> 1045000 | G16: =COUNTIFS(TRANSACTIONS!$B:$B,DATE(YEAR(RAPPORTS!$L$4),MONTH(RAPPORTS!$L$4),DAY(RAPPORTS!$L$4)),TRANSACTIONS!$D:$D,RAPPORTS!$A16,TRANSACTIONS!$E:$E,RAPPORTS!F$9) -> 5 | H16: =D16-F16 -> -773000 | J16: 200 | K16: 2 | L16: =J16*K16 -> 400
A17: APPRO W | D17: =SUMIFS(TRANSACTIONS!$H:$H,TRANSACTIONS!$B:$B,DATE(YEAR(RAPPORTS!$L$4),MONTH(RAPPORTS!$L$4),DAY(RAPPORTS!$L$4)),TRANSACTIONS!$D:$D,RAPPORTS!$A17,TRANSACTIONS!$E:$E,RAPPORTS!D$9) -> 0 | E17: 0 | F17: =SUMIFS(TRANSACTIONS!$H:$H,TRANSACTIONS!$B:$B,DATE(YEAR(RAPPORTS!$L$4),MONTH(RAPPORTS!$L$4),DAY(RAPPORTS!$L$4)),TRANSACTIONS!$D:$D,RAPPORTS!$A17,TRANSACTIONS!$E:$E,RAPPORTS!F$9) -> 0 | G17: =COUNTIFS(TRANSACTIONS!$B:$B,DATE(YEAR(RAPPORTS!$L$4),MONTH(RAPPORTS!$L$4),DAY(RAPPORTS!$L$4)),TRANSACTIONS!$D:$D,RAPPORTS!$A17,TRANSACTIONS!$E:$E,RAPPORTS!F$9) -> 0 | H17: =D17-F17 -> 0 | J17: 250 | K17: 0 | L17: =J17*K17 -> 0
A18: Proximo | D18: =SUMIFS(TRANSACTIONS!$H:$H,TRANSACTIONS!$B:$B,DATE(YEAR(RAPPORTS!$L$4),MONTH(RAPPORTS!$L$4),DAY(RAPPORTS!$L$4)),TRANSACTIONS!$D:$D,RAPPORTS!$A18,TRANSACTIONS!$E:$E,RAPPORTS!D$9) -> 0 | E18: =COUNTIFS(TRANSACTIONS!$B:$B,DATE(YEAR(RAPPORTS!$L$4),MONTH(RAPPORTS!$L$4),DAY(RAPPORTS!$L$4)),TRANSACTIONS!$D:$D,RAPPORTS!$A18,TRANSACTIONS!$E:$E,RAPPORTS!D$9) -> 0 | F18: =SUMIFS(TRANSACTIONS!$H:$H,TRANSACTIONS!$B:$B,DATE(YEAR(RAPPORTS!$L$4),MONTH(RAPPORTS!$L$4),DAY(RAPPORTS!$L$4)),TRANSACTIONS!$D:$D,RAPPORTS!$A18,TRANSACTIONS!$E:$E,RAPPORTS!F$9) -> 0 | G18: =COUNTIFS(TRANSACTIONS!$B:$B,DATE(YEAR(RAPPORTS!$L$4),MONTH(RAPPORTS!$L$4),DAY(RAPPORTS!$L$4)),TRANSACTIONS!$D:$D,RAPPORTS!$A18,TRANSACTIONS!$E:$E,RAPPORTS!F$9) -> 0 | H18: =D18-F18 -> 0 | J18: 500 | K18: 13 | L18: =K18*J18 -> 6500
A19: APPRO CASH | D19: =SUMIFS(TRANSACTIONS!$H:$H,TRANSACTIONS!$B:$B,DATE(YEAR(RAPPORTS!$L$4),MONTH(RAPPORTS!$L$4),DAY(RAPPORTS!$L$4)),TRANSACTIONS!$D:$D,RAPPORTS!$A19,TRANSACTIONS!$E:$E,RAPPORTS!D$9) -> 0 | E19: =COUNTIFS(TRANSACTIONS!$B:$B,DATE(YEAR(RAPPORTS!$L$4),MONTH(RAPPORTS!$L$4),DAY(RAPPORTS!$L$4)),TRANSACTIONS!$D:$D,RAPPORTS!$A19,TRANSACTIONS!$E:$E,RAPPORTS!D$9) -> 0 | G19: =COUNTIFS(TRANSACTIONS!$B:$B,DATE(YEAR(RAPPORTS!$L$4),MONTH(RAPPORTS!$L$4),DAY(RAPPORTS!$L$4)),TRANSACTIONS!$D:$D,RAPPORTS!$A19,TRANSACTIONS!$E:$E,RAPPORTS!F$9) -> 0 | H19: =D19-F19 -> 0 | J19: 1000 | K19: 6 | L19: =J19*K19 -> 6000
A20: 3 | D20: =SUMIFS(TRANSACTIONS!$H:$H,TRANSACTIONS!$B:$B,DATE(YEAR(RAPPORTS!$L$4),MONTH(RAPPORTS!$L$4),DAY(RAPPORTS!$L$4)),TRANSACTIONS!$D:$D,RAPPORTS!$A20,TRANSACTIONS!$E:$E,RAPPORTS!D$9) -> 0 | E20: =COUNTIFS(TRANSACTIONS!$B:$B,DATE(YEAR(RAPPORTS!$L$4),MONTH(RAPPORTS!$L$4),DAY(RAPPORTS!$L$4)),TRANSACTIONS!$D:$D,RAPPORTS!$A20,TRANSACTIONS!$E:$E,RAPPORTS!D$9) -> 0 | F20: =SUMIFS(TRANSACTIONS!$H:$H,TRANSACTIONS!$B:$B,DATE(YEAR(RAPPORTS!$L$4),MONTH(RAPPORTS!$L$4),DAY(RAPPORTS!$L$4)),TRANSACTIONS!$D:$D,RAPPORTS!$A20,TRANSACTIONS!$E:$E,RAPPORTS!F$9) -> 0 | G20: =COUNTIFS(TRANSACTIONS!$B:$B,DATE(YEAR(RAPPORTS!$L$4),MONTH(RAPPORTS!$L$4),DAY(RAPPORTS!$L$4)),TRANSACTIONS!$D:$D,RAPPORTS!$A20,TRANSACTIONS!$E:$E,RAPPORTS!F$9) -> 0 | H20: =D20-F20 -> 0 | J20: 2000 | K20: 0 | L20: =J20*K20 -> 0
A21: APPRO OM | D21: =SUMIFS(TRANSACTIONS!$H:$H,TRANSACTIONS!$B:$B,DATE(YEAR(RAPPORTS!$L$4),MONTH(RAPPORTS!$L$4),DAY(RAPPORTS!$L$4)),TRANSACTIONS!$D:$D,RAPPORTS!$A21,TRANSACTIONS!$E:$E,RAPPORTS!D$9) -> 0 | E21: =COUNTIFS(TRANSACTIONS!$B:$B,DATE(YEAR(RAPPORTS!$L$4),MONTH(RAPPORTS!$L$4),DAY(RAPPORTS!$L$4)),TRANSACTIONS!$D:$D,RAPPORTS!$A21,TRANSACTIONS!$E:$E,RAPPORTS!D$9) -> 0 | G21: =COUNTIFS(TRANSACTIONS!$B:$B,DATE(YEAR(RAPPORTS!$L$4),MONTH(RAPPORTS!$L$4),DAY(RAPPORTS!$L$4)),TRANSACTIONS!$D:$D,RAPPORTS!$A21,TRANSACTIONS!$E:$E,RAPPORTS!F$9) -> 0 | H21: =D21-F21 -> 0 | J21: 5000 | K21: 42 | L21: =J21*K21 -> 210000
A22: FREE | B22: 3705 | D22: =SUMIFS(TRANSACTIONS!$H:$H,TRANSACTIONS!$B:$B,DATE(YEAR(RAPPORTS!$L$4),MONTH(RAPPORTS!$L$4),DAY(RAPPORTS!$L$4)),TRANSACTIONS!$D:$D,RAPPORTS!$A22,TRANSACTIONS!$E:$E,RAPPORTS!D$9) -> 0 | E22: =COUNTIFS(TRANSACTIONS!$B:$B,DATE(YEAR(RAPPORTS!$L$4),MONTH(RAPPORTS!$L$4),DAY(RAPPORTS!$L$4)),TRANSACTIONS!$D:$D,RAPPORTS!$A22,TRANSACTIONS!$E:$E,RAPPORTS!D$9) -> 0 | F22: =SUMIFS(TRANSACTIONS!$H:$H,TRANSACTIONS!$B:$B,DATE(YEAR(RAPPORTS!$L$4),MONTH(RAPPORTS!$L$4),DAY(RAPPORTS!$L$4)),TRANSACTIONS!$D:$D,RAPPORTS!$A22,TRANSACTIONS!$E:$E,RAPPORTS!F$9) -> 0 | G22: =COUNTIFS(TRANSACTIONS!$B:$B,DATE(YEAR(RAPPORTS!$L$4),MONTH(RAPPORTS!$L$4),DAY(RAPPORTS!$L$4)),TRANSACTIONS!$D:$D,RAPPORTS!$A22,TRANSACTIONS!$E:$E,RAPPORTS!F$9) -> 0 | H22: =D22-F22 -> 0 | J22: 10000 | K22: 100 | L22: =J22*K22 -> 1000000
A23: CREDIT | D23: =SUMIFS(TRANSACTIONS!$H:$H,TRANSACTIONS!$B:$B,DATE(YEAR(RAPPORTS!$L$4),MONTH(RAPPORTS!$L$4),DAY(RAPPORTS!$L$4)),TRANSACTIONS!$D:$D,RAPPORTS!$A23,TRANSACTIONS!$E:$E,RAPPORTS!D$9) -> 0 | E23: =COUNTIFS(TRANSACTIONS!$B:$B,DATE(YEAR(RAPPORTS!$L$4),MONTH(RAPPORTS!$L$4),DAY(RAPPORTS!$L$4)),TRANSACTIONS!$D:$D,RAPPORTS!$A23,TRANSACTIONS!$E:$E,RAPPORTS!D$9) -> 0 | F23: =SUMIFS(TRANSACTIONS!$H:$H,TRANSACTIONS!$B:$B,DATE(YEAR(RAPPORTS!$L$4),MONTH(RAPPORTS!$L$4),DAY(RAPPORTS!$L$4)),TRANSACTIONS!$D:$D,RAPPORTS!$A23,TRANSACTIONS!$E:$E,RAPPORTS!F$9) -> 0 | G23: =COUNTIFS(TRANSACTIONS!$B:$B,DATE(YEAR(RAPPORTS!$L$4),MONTH(RAPPORTS!$L$4),DAY(RAPPORTS!$L$4)),TRANSACTIONS!$D:$D,RAPPORTS!$A23,TRANSACTIONS!$E:$E,RAPPORTS!F$9) -> 0 | H23: =D23-F23 -> 0 | L23: =SUM(L10:L22) -> 1238680
A24: KPAY | D24: =SUMIFS(TRANSACTIONS!$H:$H,TRANSACTIONS!$B:$B,DATE(YEAR(RAPPORTS!$L$4),MONTH(RAPPORTS!$L$4),DAY(RAPPORTS!$L$4)),TRANSACTIONS!$D:$D,RAPPORTS!$A24,TRANSACTIONS!$E:$E,RAPPORTS!D$9) -> 0 | E24: =COUNTIFS(TRANSACTIONS!$B:$B,DATE(YEAR(RAPPORTS!$L$4),MONTH(RAPPORTS!$L$4),DAY(RAPPORTS!$L$4)),TRANSACTIONS!$D:$D,RAPPORTS!$A24,TRANSACTIONS!$E:$E,RAPPORTS!D$9) -> 0 | F24: =SUMIFS(TRANSACTIONS!$H:$H,TRANSACTIONS!$B:$B,DATE(YEAR(RAPPORTS!$L$4),MONTH(RAPPORTS!$L$4),DAY(RAPPORTS!$L$4)),TRANSACTIONS!$D:$D,RAPPORTS!$A24,TRANSACTIONS!$E:$E,RAPPORTS!F$9) -> 0 | G24: =COUNTIFS(TRANSACTIONS!$B:$B,DATE(YEAR(RAPPORTS!$L$4),MONTH(RAPPORTS!$L$4),DAY(RAPPORTS!$L$4)),TRANSACTIONS!$D:$D,RAPPORTS!$A24,TRANSACTIONS!$E:$E,RAPPORTS!F$9) -> 0 | H24: =D24-F24 -> 0
A25: DIVERS | D25: =SUMIFS(TRANSACTIONS!$H:$H,TRANSACTIONS!$B:$B,DATE(YEAR(RAPPORTS!$L$4),MONTH(RAPPORTS!$L$4),DAY(RAPPORTS!$L$4)),TRANSACTIONS!$D:$D,RAPPORTS!$A25,TRANSACTIONS!$E:$E,RAPPORTS!D$9) -> 0 | E25: =COUNTIFS(TRANSACTIONS!$B:$B,DATE(YEAR(RAPPORTS!$L$4),MONTH(RAPPORTS!$L$4),DAY(RAPPORTS!$L$4)),TRANSACTIONS!$D:$D,RAPPORTS!$A25,TRANSACTIONS!$E:$E,RAPPORTS!D$9) -> 0 | F25: =SUMIFS(TRANSACTIONS!$H:$H,TRANSACTIONS!$B:$B,DATE(YEAR(RAPPORTS!$L$4),MONTH(RAPPORTS!$L$4),DAY(RAPPORTS!$L$4)),TRANSACTIONS!$D:$D,RAPPORTS!$A25,TRANSACTIONS!$E:$E,RAPPORTS!F$9) -> 0 | G25: =COUNTIFS(TRANSACTIONS!$B:$B,DATE(YEAR(RAPPORTS!$L$4),MONTH(RAPPORTS!$L$4),DAY(RAPPORTS!$L$4)),TRANSACTIONS!$D:$D,RAPPORTS!$A25,TRANSACTIONS!$E:$E,RAPPORTS!F$9) -> 0 | H25: =D25-F25 -> 0 | P25: 772400956
A26: Sous total Encaissement/Décaissement | D26: =SUM(D11:D25) -> 3242350 | E26: =SUM(E13:E25) -> 43 | F26: =SUM(F12:F25) -> 1772300 | G26: =+G13+G16+G17+G18+G19+G20+G21+G22+G23+G24+G25+G14+G15 -> 40 | H26: =SUM(H11:H25) -> 720050
A27: Compense demandée à la clôture
A28: Cash In demandé dans la journée | H28: =H7+H26 -> 989830
A29: Signature Agent | F29: Solde Réel | H29: =L23 -> 1238680
A30: Commentaires APPRO | F30: Cumul écart | H30: =H29-H28 -> 248850
A31: sokhna7000+21000+40000+90000+25000 | F31: Cumul écart J-1
F32: Ecart J | H32: =H30 -> 248850
F1037: 20000
D1038: Orange Money | E1038: Décaissement (-) | F1038: 10500 | I1038: REMONTEE
D1039: Orange Money | E1039: Décaissement (-) | F1039: 15000 | I1039: REMONTEE
D1040: Orange Money | E1040: Décaissement (-) | F1040: 5000 | I1040: REMONTEE
F1041: 50000 | I1041: REMONTEE
F1042: 10000 | I1042: REMONTEE
F1043: 5400 | I1043: REMONTEE
F1044: 54200 | I1044: REMONTEE
F1045: 5000 | I1045: REMONTEE
F1046: 30000 | I1046: REMONTEE
...

Sheet TRANSACTIONS
A1: 7
A2: DATE & HEURE | B2: DATE | C2: HEURE | D2: PLATEFORME | E2: OPERATION | F2: MONTANT | G2: FRAIS | H2: MONTANT TOTAL | I2: SITUATION
A3: 45389.49 | B3: =IF(A3<>"",DATE(YEAR(TRANSACTIONS!$A3),MONTH(TRANSACTIONS!$A3),DAY(TRANSACTIONS!$A3)),"") -> 45389 | C3: =IF(A3<>"",TIME(HOUR(TRANSACTIONS!$A3),MINUTE(TRANSACTIONS!$A3),SECOND(TRANSACTIONS!$A3)),"") -> 0.49033565 | D3: WAVE | E3: Encaissement (+) | F3: 1000 | H3: =IFERROR(TRANSACTIONS!$F3+TRANSACTIONS!$G3,"") -> 1000 | I3: rEMONTEE
A4: 45389.496 | B4: =IF(A4<>"",DATE(YEAR(TRANSACTIONS!$A4),MONTH(TRANSACTIONS!$A4),DAY(TRANSACTIONS!$A4)),"") -> 45389 | C4: =IF(A4<>"",TIME(HOUR(TRANSACTIONS!$A4),MINUTE(TRANSACTIONS!$A4),SECOND(TRANSACTIONS!$A4)),"") -> 0.49596065 | D4: WAVE | E4: Encaissement (+) | F4: 30000 | H4: =IFERROR(TRANSACTIONS!$F4+TRANSACTIONS!$G4,"") -> 30000 | I4: rEMONTEE
A5: 45389.497 | B5: =IF(A5<>"",DATE(YEAR(TRANSACTIONS!$A5),MONTH(TRANSACTIONS!$A5),DAY(TRANSACTIONS!$A5)),"") -> 45389 | C5: =IF(A5<>"",TIME(HOUR(TRANSACTIONS!$A5),MINUTE(TRANSACTIONS!$A5),SECOND(TRANSACTIONS!$A5)),"") -> 0.49711806 | D5: WAVE | E5: Décaissement (-) | F5: 8000 | H5: =IFERROR(TRANSACTIONS!$F5+TRANSACTIONS!$G5,"") -> 8000 | I5: REMONTEE
A6: 45389.497 | B6: =IF(A6<>"",DATE(YEAR(TRANSACTIONS!$A6),MONTH(TRANSACTIONS!$A6),DAY(TRANSACTIONS!$A6)),"") -> 45389 | C6: =IF(A6<>"",TIME(HOUR(TRANSACTIONS!$A6),MINUTE(TRANSACTIONS!$A6),SECOND(TRANSACTIONS!$A6)),"") -> 0.49721065 | D6: WAVE | E6: Décaissement (-) | F6: 10000 | H6: =IFERROR(TRANSACTIONS!$F6+TRANSACTIONS!$G6,"") -> 10000 | I6: REMONTEE
A7: 43907.403 | B7: =IF(A7<>"",DATE(YEAR(TRANSACTIONS!$A7),MONTH(TRANSACTIONS!$A7),DAY(TRANSACTIONS!$A7)),"") -> 43907 | C7: =IF(A7<>"",TIME(HOUR(TRANSACTIONS!$A7),MINUTE(TRANSACTIONS!$A7),SECOND(TRANSACTIONS!$A7)),"") -> 0.40333333 | D7: WARI | E7: Encaissement (+) | F7: 10600 | G7: =IF(AND(A7<>"",F7>1),IF(TRANSACTIONS!$E7=RAPPORTS!$F$9,0,IF(OR(TRANSACTIONS!$D7=RAPPORTS!$A$13,TRANSACTIONS!$D7=RAPPORTS!#REF!),VLOOKUP(TRANSACTIONS!$F7,FRAIS_D_ENVOI,3,TRUE),0)),"") -> #REF! | H7: =IFERROR(TRANSACTIONS!$F7+TRANSACTIONS!$G7,"")
A8: 43907.408 | B8: =IF(A8<>"",DATE(YEAR(TRANSACTIONS!$A8),MONTH(TRANSACTIONS!$A8),DAY(TRANSACTIONS!$A8)),"") -> 43907 | C8: =IF(A8<>"",TIME(HOUR(TRANSACTIONS!$A8),MINUTE(TRANSACTIONS!$A8),SECOND(TRANSACTIONS!$A8)),"") -> 0.40813657 | D8: WARI | E8: Encaissement (+) | F8: 5400 | G8: =IF(AND(A8<>"",F8>1),IF(TRANSACTIONS!$E8=RAPPORTS!$F$9,0,IF(OR(TRANSACTIONS!$D8=RAPPORTS!$A$13,TRANSACTIONS!$D8=RAPPORTS!#REF!),VLOOKUP(TRANSACTIONS!$F8,FRAIS_D_ENVOI,3,TRUE),0)),"") -> #REF! | H8: =IFERROR(TRANSACTIONS!$F8+TRANSACTIONS!$G8,"")
A9: 43907.424 | B9: =IF(A9<>"",DATE(YEAR(TRANSACTIONS!$A9),MONTH(TRANSACTIONS!$A9),DAY(TRANSACTIONS!$A9)),"") -> 43907 | C9: =IF(A9<>"",TIME(HOUR(TRANSACTIONS!$A9),MINUTE(TRANSACTIONS!$A9),SECOND(TRANSACTIONS!$A9)),"") -> 0.42447917 | D9: WARI | E9: Décaissement (-) | F9: 4700 | G9: =IF(AND(A9<>"",F9>1),IF(TRANSACTIONS!$E9=RAPPORTS!$F$9,0,IF(OR(TRANSACTIONS!$D9=RAPPORTS!$A$13,TRANSACTIONS!$D9=RAPPORTS!#REF!),VLOOKUP(TRANSACTIONS!$F9,FRAIS_D_ENVOI,3,TRUE),0)),"") -> 0 | H9: =IFERROR(TRANSACTIONS!$F9+TRANSACTIONS!$G9,"") -> 4700
A10: 43907.427 | B10: =IF(A10<>"",DATE(YEAR(TRANSACTIONS!$A10),MONTH(TRANSACTIONS!$A10),DAY(TRANSACTIONS!$A10)),"") -> 43907 | C10: =IF(A10<>"",TIME(HOUR(TRANSACTIONS!$A10),MINUTE(TRANSACTIONS!$A10),SECOND(TRANSACTIONS!$A10)),"") -> 0.42711806 | D10: Orange Money | E10: Encaissement (+) | F10: 3000 | G10: =IF(AND(A10<>"",F10>1),IF(TRANSACTIONS!$E10=RAPPORTS!$F$9,0,IF(OR(TRANSACTIONS!$D10=RAPPORTS!$A$13,TRANSACTIONS!$D10=RAPPORTS!#REF!),VLOOKUP(TRANSACTIONS!$F10,FRAIS_D_ENVOI,3,TRUE),0)),"") -> #REF! | H10: =IFERROR(TRANSACTIONS!$F10+TRANSACTIONS!$G10,"")
A11: 43907.441 | B11: =IF(A11<>"",DATE(YEAR(TRANSACTIONS!$A11),MONTH(TRANSACTIONS!$A11),DAY(TRANSACTIONS!$A11)),"") -> 43907 | C11: =IF(A11<>"",TIME(HOUR(TRANSACTIONS!$A11),MINUTE(TRANSACTIONS!$A11),SECOND(TRANSACTIONS!$A11)),"") -> 0.44050926 | D11: Orange Money | E11: Décaissement (-) | F11: 13000 | G11: =IF(AND(A11<>"",F11>1),IF(TRANSACTIONS!$E11=RAPPORTS!$F$9,0,IF(OR(TRANSACTIONS!$D11=RAPPORTS!$A$13,TRANSACTIONS!$D11=RAPPORTS!#REF!),VLOOKUP(TRANSACTIONS!$F11,FRAIS_D_ENVOI,3,TRUE),0)),"") -> 0 | H11: =IFERROR(TRANSACTIONS!$F11+TRANSACTIONS!$G11,"") -> 13000
A12: 45389.498 | B12: =IF(A12<>"",DATE(YEAR(TRANSACTIONS!$A12),MONTH(TRANSACTIONS!$A12),DAY(TRANSACTIONS!$A12)),"") -> 45389 | C12: =IF(A12<>"",TIME(HOUR(TRANSACTIONS!$A12),MINUTE(TRANSACTIONS!$A12),SECOND(TRANSACTIONS!$A12)),"") -> 0.49771991 | D12: Orange Money | E12: Décaissement (-) | F12: 4000 | H12: =IFERROR(TRANSACTIONS!$F12+TRANSACTIONS!$G12,"") -> 4000 | I12: REMONTEE
A13: 45389.498 | B13: =IF(A13<>"",DATE(YEAR(TRANSACTIONS!$A13),MONTH(TRANSACTIONS!$A13),DAY(TRANSACTIONS!$A13)),"") -> 45389 | C13: =IF(A13<>"",TIME(HOUR(TRANSACTIONS!$A13),MINUTE(TRANSACTIONS!$A13),SECOND(TRANSACTIONS!$A13)),"") -> 0.49771991 | D13: WAVE | E13: Décaissement (-) | F13: 58000 | H13: =IFERROR(TRANSACTIONS!$F13+TRANSACTIONS!$G13,"") -> 58000 | I13: REMONTEE
A14: 45389.501 | B14: =IF(A14<>"",DATE(YEAR(TRANSACTIONS!$A14),MONTH(TRANSACTIONS!$A14),DAY(TRANSACTIONS!$A14)),"") -> 45389 | C14: =IF(A14<>"",TIME(HOUR(TRANSACTIONS!$A14),MINUTE(TRANSACTIONS!$A14),SECOND(TRANSACTIONS!$A14)),"") -> 0.50112269 | D14: WAVE | E14: Encaissement (+) | F14: 7000 | H14: =IFERROR(TRANSACTIONS!$F14+TRANSACTIONS!$G14,"") -> 7000 | I14: REMONTEE
A15: 45389.511 | B15: =IF(A15<>"",DATE(YEAR(TRANSACTIONS!$A15),MONTH(TRANSACTIONS!$A15),DAY(TRANSACTIONS!$A15)),"") -> 45389 | C15: =IF(A15<>"",TIME(HOUR(TRANSACTIONS!$A15),MINUTE(TRANSACTIONS!$A15),SECOND(TRANSACTIONS!$A15)),"") -> 0.51127315 | D15: WAVE | E15: Encaissement (+) | F15: 5000 | H15: =IFERROR(TRANSACTIONS!$F15+TRANSACTIONS!$G15,"") -> 5000 | I15: REMONTEE
A16: 45389.511 | B16: =IF(A16<>"",DATE(YEAR(TRANSACTIONS!$A16),MONTH(TRANSACTIONS!$A16),DAY(TRANSACTIONS!$A16)),"") -> 45389 | C16: =IF(A16<>"",TIME(HOUR(TRANSACTIONS!$A16),MINUTE(TRANSACTIONS!$A16),SECOND(TRANSACTIONS!$A16)),"") -> 0.51145833 | D16: WAVE | E16: Encaissement (+) | F16: 35500 | H16: =IFERROR(TRANSACTIONS!$F16+TRANSACTIONS!$G16,"") -> 35500 | I16: REMONTEE
A17: 45389.512 | B17: =IF(A17<>"",DATE(YEAR(TRANSACTIONS!$A17),MONTH(TRANSACTIONS!$A17),DAY(TRANSACTIONS!$A17)),"") -> 45389 | C17: =IF(A17<>"",TIME(HOUR(TRANSACTIONS!$A17),MINUTE(TRANSACTIONS!$A17),SECOND(TRANSACTIONS!$A17)),"") -> 0.51184028 | D17: Orange Money | E17: Encaissement (+) | F17: 27000 | H17: =IFERROR(TRANSACTIONS!$F17+TRANSACTIONS!$G17,"") -> 27000 | I17: REMONTEE
A18: 45389.513 | B18: =IF(A18<>"",DATE(YEAR(TRANSACTIONS!$A18),MONTH(TRANSACTIONS!$A18),DAY(TRANSACTIONS!$A18)),"") -> 45389 | C18: =IF(A18<>"",TIME(HOUR(TRANSACTIONS!$A18),MINUTE(TRANSACTIONS!$A18),SECOND(TRANSACTIONS!$A18)),"") -> 0.51261574 | D18: WAVE | E18: Encaissement (+) | F18: 5000 | H18: =IFERROR(TRANSACTIONS!$F18+TRANSACTIONS!$G18,"") -> 5000 | I18: REMONTEE
A19: 45389.514 | B19: =IF(A19<>"",DATE(YEAR(TRANSACTIONS!$A19),MONTH(TRANSACTIONS!$A19),DAY(TRANSACTIONS!$A19)),"") -> 45389 | C19: =IF(A19<>"",TIME(HOUR(TRANSACTIONS!$A19),MINUTE(TRANSACTIONS!$A19),SECOND(TRANSACTIONS!$A19)),"") -> 0.51383102 | D19: WAVE | E19: Encaissement (+) | F19: 500 | H19: =IFERROR(TRANSACTIONS!$F19+TRANSACTIONS!$G19,"") -> 500 | I19: REMONTEE
A20: 45389.534 | B20: =IF(A20<>"",DATE(YEAR(TRANSACTIONS!$A20),MONTH(TRANSACTIONS!$A20),DAY(TRANSACTIONS!$A20)),"") -> 45389 | C20: =IF(A20<>"",TIME(HOUR(TRANSACTIONS!$A20),MINUTE(TRANSACTIONS!$A20),SECOND(TRANSACTIONS!$A20)),"") -> 0.53386574 | D20: WAVE | E20: Décaissement (-) | F20: 7000 | H20: =IFERROR(TRANSACTIONS!$F20+TRANSACTIONS!$G20,"") -> 7000 | I20: REMONTEE
A21: 45389.534 | B21: =IF(A21<>"",DATE(YEAR(TRANSACTIONS!$A21),MONTH(TRANSACTIONS!$A21),DAY(TRANSACTIONS!$A21)),"") -> 45389 | C21: =IF(A21<>"",TIME(HOUR(TRANSACTIONS!$A21),MINUTE(TRANSACTIONS!$A21),SECOND(TRANSACTIONS!$A21)),"") -> 0.53387731 | D21: WAVE | E21: Décaissement (-) | F21: 100000 | H21: =IFERROR(TRANSACTIONS!$F21+TRANSACTIONS!$G21,"") -> 100000 | I21: REMONTEE
A22: 43907.54 | B22: =IF(A22<>"",DATE(YEAR(TRANSACTIONS!$A22),MONTH(TRANSACTIONS!$A22),DAY(TRANSACTIONS!$A22)),"") -> 43907 | C22: =IF(A22<>"",TIME(HOUR(TRANSACTIONS!$A22),MINUTE(TRANSACTIONS!$A22),SECOND(TRANSACTIONS!$A22)),"") -> 0.54048611 | D22: Orange Money | E22: Décaissement (-) | F22: 5000 | G22: =IF(AND(A22<>"",F22>1),IF(TRANSACTIONS!$E22=RAPPORTS!$F$9,0,IF(OR(TRANSACTIONS!$D22=RAPPORTS!$A$13,TRANSACTIONS!$D22=RAPPORTS!#REF!),VLOOKUP(TRANSACTIONS!$F22,FRAIS_D_ENVOI,3,TRUE),0)),"") -> 0 | H22: =IFERROR(TRANSACTIONS!$F22+TRANSACTIONS!$G22,"") -> 5000 | K22: 108
A23: 43907.552 | B23: =IF(A23<>"",DATE(YEAR(TRANSACTIONS!$A23),MONTH(TRANSACTIONS!$A23),DAY(TRANSACTIONS!$A23)),"") -> 43907 | C23: =IF(A23<>"",TIME(HOUR(TRANSACTIONS!$A23),MINUTE(TRANSACTIONS!$A23),SECOND(TRANSACTIONS!$A23)),"") -> 0.55230324 | D23: Orange Money | E23: Décaissement (-) | F23: 9000 | G23: =IF(AND(A23<>"",F23>1),IF(TRANSACTIONS!$E23=RAPPORTS!$F$9,0,IF(OR(TRANSACTIONS!$D23=RAPPORTS!$A$13,TRANSACTIONS!$D23=RAPPORTS!#REF!),VLOOKUP(TRANSACTIONS!$F23,FRAIS_D_ENVOI,3,TRUE),0)),"") -> 0 | H23: =IFERROR(TRANSACTIONS!$F23+TRANSACTIONS!$G23,"") -> 9000
A24: 43907.553 | B24: =IF(A24<>"",DATE(YEAR(TRANSACTIONS!$A24),MONTH(TRANSACTIONS!$A24),DAY(TRANSACTIONS!$A24)),"") -> 43907 | C24: =IF(A24<>"",TIME(HOUR(TRANSACTIONS!$A24),MINUTE(TRANSACTIONS!$A24),SECOND(TRANSACTIONS!$A24)),"") -> 0.5531713 | D24: Orange Money | E24: Décaissement (-) | F24: 28600 | G24: =IF(AND(A24<>"",F24>1),IF(TRANSACTIONS!$E24=RAPPORTS!$F$9,0,IF(OR(TRANSACTIONS!$D24=RAPPORTS!$A$13,TRANSACTIONS!$D24=RAPPORTS!#REF!),VLOOKUP(TRANSACTIONS!$F24,FRAIS_D_ENVOI,3,TRUE),0)),"") -> 0 | H24: =IFERROR(TRANSACTIONS!$F24+TRANSACTIONS!$G24,"") -> 28600 | J24: =IF(G24<>"",$J$1*G24,"") -> 0
A25: 43907.558 | B25: =IF(A25<>"",DATE(YEAR(TRANSACTIONS!$A25),MONTH(TRANSACTIONS!$A25),DAY(TRANSACTIONS!$A25)),"") -> 43907 | C25: =IF(A25<>"",TIME(HOUR(TRANSACTIONS!$A25),MINUTE(TRANSACTIONS!$A25),SECOND(TRANSACTIONS!$A25)),"") -> 0.55804398 | D25: Orange Money | E25: Décaissement (-) | F25: 5000 | G25: =IF(AND(A25<>"",F25>1),IF(TRANSACTIONS!$E25=RAPPORTS!$F$9,0,IF(OR(TRANSACTIONS!$D25=RAPPORTS!$A$13,TRANSACTIONS!$D25=RAPPORTS!#REF!),VLOOKUP(TRANSACTIONS!$F25,FRAIS_D_ENVOI,3,TRUE),0)),"") -> 0 | H25: =IFERROR(TRANSACTIONS!$F25+TRANSACTIONS!$G25,"") -> 5000 | J25: =IF(G25<>"",$J$1*G25,"") -> 0
A26: 43907.558 | B26: =IF(A26<>"",DATE(YEAR(TRANSACTIONS!$A26),MONTH(TRANSACTIONS!$A26),DAY(TRANSACTIONS!$A26)),"") -> 43907 | C26: =IF(A26<>"",TIME(HOUR(TRANSACTIONS!$A26),MINUTE(TRANSACTIONS!$A26),SECOND(TRANSACTIONS!$A26)),"") -> 0.55818287 | D26: Orange Money | E26: Décaissement (-) | F26: 2800 | G26: =IF(AND(A26<>"",F26>1),IF(TRANSACTIONS!$E26=RAPPORTS!$F$9,0,IF(OR(TRANSACTIONS!$D26=RAPPORTS!$A$13,TRANSACTIONS!$D26=RAPPORTS!#REF!),VLOOKUP(TRANSACTIONS!$F26,FRAIS_D_ENVOI,3,TRUE),0)),"") -> 0 | H26: =IFERROR(TRANSACTIONS!$F26+TRANSACTIONS!$G26,"") -> 2800 | J26: =IF(G26<>"",$J$1*G26,"") -> 0
A27: 43907.575 | B27: =IF(A27<>"",DATE(YEAR(TRANSACTIONS!$A27),MONTH(TRANSACTIONS!$A27),DAY(TRANSACTIONS!$A27)),"") -> 43907 | C27: =IF(A27<>"",TIME(HOUR(TRANSACTIONS!$A27),MINUTE(TRANSACTIONS!$A27),SECOND(TRANSACTIONS!$A27)),"") -> 0.57528935 | D27: Orange Money | E27: Encaissement (+) | F27: 15700 | G27: =IF(AND(A27<>"",F27>1),IF(TRANSACTIONS!$E27=RAPPORTS!$F$9,0,IF(OR(TRANSACTIONS!$D27=RAPPORTS!$A$13,TRANSACTIONS!$D27=RAPPORTS!#REF!),VLOOKUP(TRANSACTIONS!$F27,FRAIS_D_ENVOI,3,TRUE),0)),"") -> #REF! | H27: =IFERROR(TRANSACTIONS!$F27+TRANSACTIONS!$G27,"") | J27: =IF(G27<>"",$J$1*G27,"") -> #REF!
A28: 43907.581 | B28: =IF(A28<>"",DATE(YEAR(TRANSACTIONS!$A28),MONTH(TRANSACTIONS!$A28),DAY(TRANSACTIONS!$A28)),"") -> 43907 | C28: =IF(A28<>"",TIME(HOUR(TRANSACTIONS!$A28),MINUTE(TRANSACTIONS!$A28),SECOND(TRANSACTIONS!$A28)),"") -> 0.58082176 | D28: Orange Money | E28: Encaissement (+) | F28: 10500 | G28: =IF(AND(A28<>"",F28>1),IF(TRANSACTIONS!$E28=RAPPORTS!$F$9,0,IF(OR(TRANSACTIONS!$D28=RAPPORTS!$A$13,TRANSACTIONS!$D28=RAPPORTS!#REF!),VLOOKUP(TRANSACTIONS!$F28,FRAIS_D_ENVOI,3,TRUE),0)),"") -> #REF! | H28: =IFERROR(TRANSACTIONS!$F28+TRANSACTIONS!$G28,"") | J28: =IF(G28<>"",$J$1*G28,"") -> #REF!
A29: 43907.632 | B29: =IF(A29<>"",DATE(YEAR(TRANSACTIONS!$A29),MONTH(TRANSACTIONS!$A29),DAY(TRANSACTIONS!$A29)),"") -> 43907 | C29: =IF(A29<>"",TIME(HOUR(TRANSACTIONS!$A29),MINUTE(TRANSACTIONS!$A29),SECOND(TRANSACTIONS!$A29)),"") -> 0.63219907 | D29: Orange Money | E29: Encaissement (+) | F29: 10000 | G29: =IF(AND(A29<>"",F29>1),IF(TRANSACTIONS!$E29=RAPPORTS!$F$9,0,IF(OR(TRANSACTIONS!$D29=RAPPORTS!$A$13,TRANSACTIONS!$D29=RAPPORTS!#REF!),VLOOKUP(TRANSACTIONS!$F29,FRAIS_D_ENVOI,3,TRUE),0)),"") -> #REF! | H29: =IFERROR(TRANSACTIONS!$F29+TRANSACTIONS!$G29,"") | J29: =IF(G29<>"",$J$1*G29,"") -> #REF!
A30: 45389.534 | B30: =IF(A30<>"",DATE(YEAR(TRANSACTIONS!$A30),MONTH(TRANSACTIONS!$A30),DAY(TRANSACTIONS!$A30)),"") -> 45389 | C30: =IF(A30<>"",TIME(HOUR(TRANSACTIONS!$A30),MINUTE(TRANSACTIONS!$A30),SECOND(TRANSACTIONS!$A30)),"") -> 0.53388889 | D30: WAVE | E30: Décaissement (-) | F30: 155000 | H30: =IFERROR(TRANSACTIONS!$F30+TRANSACTIONS!$G30,"") -> 155000 | I30: REMONTEE | J30: =IF(G30<>"",$J$1*G30,"")
A31: 45389.534 | B31: =IF(A31<>"",DATE(YEAR(TRANSACTIONS!$A31),MONTH(TRANSACTIONS!$A31),DAY(TRANSACTIONS!$A31)),"") -> 45389 | C31: =IF(A31<>"",TIME(HOUR(TRANSACTIONS!$A31),MINUTE(TRANSACTIONS!$A31),SECOND(TRANSACTIONS!$A31)),"") -> 0.53395833 | D31: WAVE | E31: Encaissement (+) | F31: 10000 | H31: =IFERROR(TRANSACTIONS!$F31+TRANSACTIONS!$G31,"") -> 10000 | I31: REMONTEE | J31: =IF(G31<>"",$J$1*G31,"")
A32: 43907.646 | B32: =IF(A32<>"",DATE(YEAR(TRANSACTIONS!$A32),MONTH(TRANSACTIONS!$A32),DAY(TRANSACTIONS!$A32)),"") -> 43907 | C32: =IF(A32<>"",TIME(HOUR(TRANSACTIONS!$A32),MINUTE(TRANSACTIONS!$A32),SECOND(TRANSACTIONS!$A32)),"") -> 0.64625 | D32: Orange Money | E32: Encaissement (+) | F32: 30000 | G32: =IF(AND(A32<>"",F32>1),IF(TRANSACTIONS!$E32=RAPPORTS!$F$9,0,IF(OR(TRANSACTIONS!$D32=RAPPORTS!$A$13,TRANSACTIONS!$D32=RAPPORTS!#REF!),VLOOKUP(TRANSACTIONS!$F32,FRAIS_D_ENVOI,3,TRUE),0)),"") -> #REF! | H32: =IFERROR(TRANSACTIONS!$F32+TRANSACTIONS!$G32,"") | J32: =IF(G32<>"",$J$1*G32,"") -> #REF!
A33: 43907.647 | B33: =IF(A33<>"",DATE(YEAR(TRANSACTIONS!$A33),MONTH(TRANSACTIONS!$A33),DAY(TRANSACTIONS!$A33)),"") -> 43907 | C33: =IF(A33<>"",TIME(HOUR(TRANSACTIONS!$A33),MINUTE(TRANSACTIONS!$A33),SECOND(TRANSACTIONS!$A33)),"") -> 0.64708333 | D33: Orange Money | E33: Encaissement (+) | F33: 2500 | G33: =IF(AND(A33<>"",F33>1),IF(TRANSACTIONS!$E33=RAPPORTS!$F$9,0,IF(OR(TRANSACTIONS!$D33=RAPPORTS!$A$13,TRANSACTIONS!$D33=RAPPORTS!#REF!),VLOOKUP(TRANSACTIONS!$F33,FRAIS_D_ENVOI,3,TRUE),0)),"") -> #REF! | H33: =IFERROR(TRANSACTIONS!$F33+TRANSACTIONS!$G33,"") | J33: =IF(G33<>"",$J$1*G33,"") -> #REF!
A34: 45389.534 | B34: =IF(A34<>"",DATE(YEAR(TRANSACTIONS!$A34),MONTH(TRANSACTIONS!$A34),DAY(TRANSACTIONS!$A34)),"") -> 45389 | C34: =IF(A34<>"",TIME(HOUR(TRANSACTIONS!$A34),MINUTE(TRANSACTIONS!$A34),SECOND(TRANSACTIONS!$A34)),"") -> 0.53396991 | D34: WAVE | E34: Encaissement (+) | F34: 30500 | H34: =IFERROR(TRANSACTIONS!$F34+TRANSACTIONS!$G34,"") -> 30500 | I34: REMONTEE | J34: =IF(G34<>"",$J$1*G34,"")
A35: 43907.655 | B35: =IF(A35<>"",DATE(YEAR(TRANSACTIONS!$A35),MONTH(TRANSACTIONS!$A35),DAY(TRANSACTIONS!$A35)),"") -> 43907 | C35: =IF(A35<>"",TIME(HOUR(TRANSACTIONS!$A35),MINUTE(TRANSACTIONS!$A35),SECOND(TRANSACTIONS!$A35)),"") -> 0.65508102 | D35: WARI | E35: Encaissement (+) | F35: 21000 | G35: =IF(AND(A35<>"",F35>1),IF(TRANSACTIONS!$E35=RAPPORTS!$F$9,0,IF(OR(TRANSACTIONS!$D35=RAPPORTS!$A$13,TRANSACTIONS!$D35=RAPPORTS!#REF!),VLOOKUP(TRANSACTIONS!$F35,FRAIS_D_ENVOI,3,TRUE),0)),"") -> #REF! | H35: =IFERROR(TRANSACTIONS!$F35+TRANSACTIONS!$G35,"") | J35: =IF(G35<>"",$J$1*G35,"") -> #REF!
A36: 45389.535 | B36: =IF(A36<>"",DATE(YEAR(TRANSACTIONS!$A36),MONTH(TRANSACTIONS!$A36),DAY(TRANSACTIONS!$A36)),"") -> 45389 | C36: =IF(A36<>"",TIME(HOUR(TRANSACTIONS!$A36),MINUTE(TRANSACTIONS!$A36),SECOND(TRANSACTIONS!$A36)),"") -> 0.53498843 | D36: WAVE | E36: Décaissement (-) | F36: 10000 | H36: =IFERROR(TRANSACTIONS!$F36+TRANSACTIONS!$G36,"") -> 10000 | I36: rEMONTEE | J36: =IF(G36<>"",$J$1*G36,"")
A37: 43907.664 | B37: =IF(A37<>"",DATE(YEAR(TRANSACTIONS!$A37),MONTH(TRANSACTIONS!$A37),DAY(TRANSACTIONS!$A37)),"") -> 43907 | C37: =IF(A37<>"",TIME(HOUR(TRANSACTIONS!$A37),MINUTE(TRANSACTIONS!$A37),SECOND(TRANSACTIONS!$A37)),"") -> 0.66363426 | D37: WARI | E37: Encaissement (+) | F37: 30000 | G37: =IF(AND(A37<>"",F37>1),IF(TRANSACTIONS!$E37=RAPPORTS!$F$9,0,IF(OR(TRANSACTIONS!$D37=RAPPORTS!$A$13,TRANSACTIONS!$D37=RAPPORTS!#REF!),VLOOKUP(TRANSACTIONS!$F37,FRAIS_D_ENVOI,3,TRUE),0)),"") -> #REF! | H37: =IFERROR(TRANSACTIONS!$F37+TRANSACTIONS!$G37,"") | J37: =IF(G37<>"",$J$1*G37,"") -> #REF!
A38: 43907.673 | B38: =IF(A38<>"",DATE(YEAR(TRANSACTIONS!$A38),MONTH(TRANSACTIONS!$A38),DAY(TRANSACTIONS!$A38)),"") -> 43907 | C38: =IF(A38<>"",TIME(HOUR(TRANSACTIONS!$A38),MINUTE(TRANSACTIONS!$A38),SECOND(TRANSACTIONS!$A38)),"") -> 0.6727662 | D38: Orange Money | E38: Décaissement (-) | F38: 10000 | G38: =IF(AND(A38<>"",F38>1),IF(TRANSACTIONS!$E38=RAPPORTS!$F$9,0,IF(OR(TRANSACTIONS!$D38=RAPPORTS!$A$13,TRANSACTIONS!$D38=RAPPORTS!#REF!),VLOOKUP(TRANSACTIONS!$F38,FRAIS_D_ENVOI,3,TRUE),0)),"") -> 0 | H38: =IFERROR(TRANSACTIONS!$F38+TRANSACTIONS!$G38,"") -> 10000 | J38: =IF(G38<>"",$J$1*G38,"") -> 0
A39: 43907.673 | B39: =IF(A39<>"",DATE(YEAR(TRANSACTIONS!$A39),MONTH(TRANSACTIONS!$A39),DAY(TRANSACTIONS!$A39)),"") -> 43907 | C39: =IF(A39<>"",TIME(HOUR(TRANSACTIONS!$A39),MINUTE(TRANSACTIONS!$A39),SECOND(TRANSACTIONS!$A39)),"") -> 0.67344907 | D39: Orange Money | E39: Décaissement (-) | F39: 7000 | G39: =IF(AND(A39<>"",F39>1),IF(TRANSACTIONS!$E39=RAPPORTS!$F$9,0,IF(OR(TRANSACTIONS!$D39=RAPPORTS!$A$13,TRANSACTIONS!$D39=RAPPORTS!#REF!),VLOOKUP(TRANSACTIONS!$F39,FRAIS_D_ENVOI,3,TRUE),0)),"") -> 0 | H39: =IFERROR(TRANSACTIONS!$F39+TRANSACTIONS!$G39,"") -> 7000 | J39: =IF(G39<>"",$J$1*G39,"") -> 0
A40: 43907.674 | B40: =IF(A40<>"",DATE(YEAR(TRANSACTIONS!$A40),MONTH(TRANSACTIONS!$A40),DAY(TRANSACTIONS!$A40)),"") -> 43907 | C40: =IF(A40<>"",TIME(HOUR(TRANSACTIONS!$A40),MINUTE(TRANSACTIONS!$A40),SECOND(TRANSACTIONS!$A40)),"") -> 0.67353009 | D40: Orange Money | E40: Encaissement (+) | F40: 3000 | G40: =IF(AND(A40<>"",F40>1),IF(TRANSACTIONS!$E40=RAPPORTS!$F$9,0,IF(OR(TRANSACTIONS!$D40=RAPPORTS!$A$13,TRANSACTIONS!$D40=RAPPORTS!#REF!),VLOOKUP(TRANSACTIONS!$F40,FRAIS_D_ENVOI,3,TRUE),0)),"") -> #REF! | H40: =IFERROR(TRANSACTIONS!$F40+TRANSACTIONS!$G40,"") | J40: =IF(G40<>"",$J$1*G40,"") -> #REF!
...

Sheet Feuil2

Sheet Feuil5
E5006: =E5006:E5031 -> 0
